Workbook

Sheet Estructura Costos
A1: ESTRUCTURA DE COSTOS - ROTISERIA NINO (BOSIN S.A.)
A2: Base: ultimos 31 dias (16/02/2026 - 18/03/2026) desestacionalizado | Elaborado: Marzo 2026
A4: 1. VENTAS
A5: Concepto | B5: Monto Mensual ($) | C5: % s/Ventas | D5: Tasa/Base | E5: Notas
A6: VENTAS (facturacion bruta, IVA incluido) | B6: 11050346 | C6: 100.0% | E6: Factura B 97% - precio de gondola incluye IVA
A7: Nota: los precios del POS incluyen IVA (Factura B). V es la facturacion real.
A8: IVA estimado contenido en V (21%) | B8: =ROUND(-B6*21/121,0) -> -1917829 | E8: Referencia - no se resta (ya esta dentro de V)
A9: Tickets promedio/mes: 1,171 | Ticket prom: $9,437
A10: Efectivo 47.1% | Debito 32.7% | Credito 9.6% | Billetera 10.6%
A12: 2. COSTO DE MERCADERIA VENDIDA (CMV)
A13: Concepto | B13: Monto Mensual ($) | C13: % s/Ventas | D13: % del CMV | E13: Insumos principales
A14: COSTO TOTAL INSUMOS | B14: =-B6*0.7 -> -7735242.2 | C14: 70.0% | D14: 100% | E14: Margen bruto 30% s/PVP (dato del sistema)
A15: Empanadas | B15: -3855659 | C15: 34.9% | D15: 50% | E15: Carne, masa, queso, verdura, aceite
A16: Carnes elaboradas | B16: -1709147 | C16: 15.5% | D16: 22% | E16: Matambre, pernil, lengua, pollo, condimentos
A17: Pizzas y canelones | B17: -660855 | C17: 6.0% | D17: 9% | E17: Harina, muzzarella, salsa, carne, verdura
A18: Milanesas | B18: -431885 | C18: 3.9% | D18: 6% | E18: Carne, pan rallado, huevo, aceite
A19: Salsas | B19: -163088 | C19: 1.5% | D19: 2% | E19: Tomate, carne, condimentos
A20: Otros elaborados | B20: -914608 | C20: 8.3% | D20: 12% | E20: Varios (tartas, fiambres, preparaciones)
A21: MARGEN BRUTO | B21: =B6+B14 -> 3315103.8 | C21: 30.0% | E21: Ventas - CMV
A22: Sensibilizar: 25%, 30%, 35% (ver hoja Sensibilizacion)
A24: 3. COSTOS FIJOS
A25: Concepto | B25: Monto Mensual ($) | C25: % s/Ventas | D25: Tasa/Base | E25: Notas
A26: 3.1 SUELDOS Y CARGAS SOCIALES
A27: Sueldos brutos (3 empleados) | B27: -3540822 | C27: 32.0% | D27: $1,180,274 c/u | E27: CCT 130/75 Aux.Esp.A (Mar 2026)
A28: - Remunerativo | B28: -3240822 | D28: $1,080,274 c/u | E28: Base contribuciones (F.930)
A29: - No Remunerativo | B29: -300000 | D29: $100,000 c/u | E29: No genera cargas patronales
A30: Contribuciones patronales (F.930) | B30: =SUM(B31:B36) -> -963820 | C30: 8.7% | D30: 29.74% s/rem | E30: Base: celda B28 (solo remunerativo)
A31: - Jubilacion (SIPA) | B31: =ROUND(B28*0.1271,0) -> -411908 | D31: 12.71% | E31: Ley 24.241. Alicuota NO MiPyME servicios/comercio
A32: - PAMI (Ley 19.032) | B32: =ROUND(B28*0.0158,0) -> -51205 | D32: 1.58% | E32: Ley 19.032 Art. 8
A33: - Asignaciones Familiares | B33: =ROUND(B28*0.0556,0) -> -180190 | D33: 5.56% | E33: Ley 24.714 Art. 5
A34: - Fondo Nacional de Empleo | B34: =ROUND(B28*0.0089,0) -> -28843 | D34: 0.89% | E34: Ley 24.013 Art. 145
A35: - Obra Social patronal | B35: =ROUND(B28*0.06,0) -> -194449 | D35: 6.00% | E35: Ley 23.660 Art. 16
A36: - ART (estimado) | B36: =ROUND(B28*0.03,0) -> -97225 | D36: ~3.00% | E36: Ley 24.557. Varia segun siniestralidad
A37: SAC proporcional (1/12) | B37: -379586 | C37: 3.4% | E37: Aguinaldo s/(rem + presentismo + cargas)
A38: Seguro Vida Obligatorio | B38: -1500 | D38: ~$500 c/u | E38: Decreto 1567/74
A39: Presentismo (Art. 40 CCT 130/75) | B39: -350388 | C39: 3.2% | D39: 8.33% s/basico | E39: Bruto $270,069 + CP $80,319
A40: Provision vacaciones (14 dias) | B40: -196217 | C40: 1.8% | E40: Art.150 LCT - bruto $151,239 + CP $44,978
A41: SUBTOTAL LABORAL | B41: =B27+B30+B37+B38+B39+B40 -> -5432333 | C41: 49.2%
A43: 3.2 SERVICIOS (prorrateo rotiseria)
A44: Gas natural (250 m3/mes) | B44: -132909 | C44: 1.2% | D44: $308/m3+imp | E44: Ecogas Cuyana SGP P1-P2 (ENARGAS Res 89/2026)
...

Sheet Simulador
A1: SIMULADOR DE COSTOS - ROTISERIA NINO
A2: Modifique parametros (amarillo) y active/desactive costos (Incluir: SI/NO). El resultado se recalcula en tiempo real.
A4: RESULTADO EN VIVO (se actualiza al modificar cualquier celda amarilla)
A5: RESULTADO NETO SIMULADO | C5: =C63 -> -3633707 | E5: =IF(B10>0,C63/B10,0) -> -0.32883197 | F5: Ver detalle en filas 56-67
A7: PARAMETROS (celdas amarillas = editables, modificar para simular)
A8: Parametro | B8: Valor | F8: Nota
A9: Cambie cualquier valor amarillo. Todo se recalcula automaticamente abajo.
A10: Ventas mensuales ($) | B10: 11050346 | F10: Facturacion mensual desestacionalizada del POS
A11: Margen bruto (%) | B11: 0.3 | F11: POS rentabilidad_factor. 0.30 = 30%
A12: Cantidad de empleados | B12: 3 | F12: Empleados asignados a rotiseria
A13: Sueldo remunerativo c/u ($) | B13: 1080274 | F13: CCT 130/75 Aux.Esp.A - base contribuciones F.930
A14: Sueldo no remunerativo c/u ($) | B14: 100000 | F14: Acuerdo paritario - no genera cargas patronales
A15: Contribuciones patronales (%) | B15: 0.2974 | F15: 29.74% NO MiPyME. Si MiPyME: cambiar a ~0.26
A16: Gas consumo (m3/mes) | B16: 250 | F16: Horno convector + cocina. Ecogas Cuyana
A17: Electricidad consumo (kWh/mes) | B17: 500 | F17: Vitrina + heladera + campana + iluminacion
A18: Tasa comision credito (%) | B18: 0.03 | F18: Procesadora tarjetas credito. Promedio mercado
A19: Tasa comision debito (%) | B19: 0.012 | F19: Procesadora tarjetas debito
A20: Tasa comision billetera (%) | B20: 0.015 | F20: Mercado Pago y otras
A21: TNA costo financiero (%) | B21: 0.4 | F21: Tasa Nominal Anual credito comercial Mar 2026
... A24: Merma / descarte (%) | B24: 0.05 | F24: Tipico rotiseria 3-8%. AJUSTAR con medicion real
A26: COSTOS FIJOS (columna Incluir: SI/NO para activar o desactivar cada costo)
A27: Concepto | B27: Incluir? | C27: Monto ($) | D27: Incluido ($) | E27: % s/V | F27: Formula / Nota
A28: Sueldos brutos | B28: SI | C28: =(B13+B14)*B12 -> 3540822 | D28: =IF(B28="SI",C28,0) -> 3540822 | E28: =IF(B10>0,D28/B10,0) -> 0.32042635 | F28: (Rem + NR) x Empleados
A29: Contribuciones patronales (F.930) | B29: SI | C29: =ROUND(B13*B12*B15,0) -> 963820 | D29: =IF(B29="SI",C29,0) -> 963820 | E29: =IF(B10>0,D29/B10,0) -> 0.087220798 | F29: Rem x Empl x CP% (solo s/remunerativo)
A30: SAC proporcional (1/12) | B30: SI | C30: =ROUND((B13*B12+ROUND(B13/12,0)*B12+ROUND(B13*B12*B15,0)+ROUND(ROUND(B13/12,0)*B12*B15,0))/12,0) -> 379586 | D30: =IF(B30="SI",C30,0) -> 379586 | E30: =IF(B10>0,D30/B10,0) -> 0.034350599 | F30: (rem+pres+CP_rem+CP_pres)/12. LCT Art.121
A31: Presentismo (8.33% Art.40 CCT 130/75) | B31: SI | C31: =ROUND(ROUND(B13/12,0)*B12*(1+B15),0) -> 350388 | D31: =IF(B31="SI",C31,0) -> 350388 | E31: =IF(B10>0,D31/B10,0) -> 0.031708328 | F31: SB_REM/12 x NE x (1+CP%). Remunerativo
A32: Vacaciones (14 dias Art.150 LCT) | B32: SI | C32: =ROUND(ROUND(B13/25*14/12,0)*B12*(1+B15),0) -> 196217 | D32: =IF(B32="SI",C32,0) -> 196217 | E32: =IF(B10>0,D32/B10,0) -> 0.017756639 | F32: SB_REM/25 x 14d/12m x NE x (1+CP%)
A33: Seguro Vida Obligatorio | B33: SI | C33: 1500 | D33: =IF(B33="SI",C33,0) -> 1500 | E33: =IF(B10>0,D33/B10,0) -> 0.00013574236 | F33: Dto. 1567/74. Editable
A34: Gas natural | B34: SI | C34: =ROUND((24129+B16*307.77)*1.315,0) -> 132909 | D34: =IF(B34="SI",C34,0) -> 132909 | E34: =IF(B10>0,D34/B10,0) -> 0.012027587 | F34: (CF+m3x$/m3)x1.315. ENARGAS
A35: Electricidad | B35: SI | C35: =ROUND((16114/2+B17*233.58)*1.39,0) -> 173537 | D35: =IF(B35="SI",C35,0) -> 173537 | E35: =IF(B10>0,D35/B10,0) -> 0.015704214 | F35: (CF/2+kWhx$/kWh)x1.39. EPRE
A36: Descartables / packaging | B36: SI | C36: 80000 | D36: =IF(B36="SI",C36,0) -> 80000 | E36: =IF(B10>0,D36/B10,0) -> 0.0072395923 | F36: Bandejas, bolsas, film. Editable
A37: Mantenimiento equipos | B37: SI | C37: 30000 | D37: =IF(B37="SI",C37,0) -> 30000 | E37: =IF(B10>0,D37/B10,0) -> 0.0027148471 | F37: Service horno, heladeras. Editable
A38: Seguros (incendio, RC) | B38: SI | C38: 25000 | D38: =IF(B38="SI",C38,0) -> 25000 | E38: =IF(B10>0,D38/B10,0) -> 0.0022623726 | F38: Prorrateo por m2. Editable
A39: Indumentaria / EPP | B39: SI | C39: 15000 | D39: =IF(B39="SI",C39,0) -> 15000 | E39: =IF(B10>0,D39/B10,0) -> 0.0013574236 | F39: Delantales, gorros, guantes. Editable
A40: Agua (prorrateo) | B40: SI | C40: 15000 | D40: =IF(B40="SI",C40,0) -> 15000 | E40: =IF(B10>0,D40/B10,0) -> 0.0013574236 | F40: Limpieza y coccion. Editable
A41: Habilitacion bromatologica | B41: SI | C41: 12000 | D41: =IF(B41="SI",C41,0) -> 12000 | E41: =IF(B10>0,D41/B10,0) -> 0.0010859388 | F41: Anual / 12. Editable
A42: Habilitacion municipal | B42: SI | C42: 8000 | D42: =IF(B42="SI",C42,0) -> 8000 | E42: =IF(B10>0,D42/B10,0) -> 0.00072395923 | F42: Tasa comercio Lujan / 12. Editable
A43: TOTAL COSTOS FIJOS | C43: =SUM(C28:C42) -> 5923779 | D43: =SUM(D28:D42) -> 5923779 | E43: =IF(B10>0,D43/B10,0) -> 0.53607181 | F43: Suma solo items con SI
A45: COSTOS VARIABLES (columna Incluir: SI/NO para activar o desactivar)
A46: Concepto | B46: Incluir? | C46: Monto ($) | D46: Incluido ($) | E46: % s/V | F46: Formula / Nota
...

Sheet Ventas Mensuales
A1: VENTAS MENSUALES ROTISERIA - DETALLE
A3: Periodo | B3: Ventas ($) | C3: Tickets | D3: Items | E3: Ticket Prom | F3: Efectivo ($) | G3: Debito ($) | H3: Credito ($) | I3: Billetera ($)
A4: 2024-10 | B4: 7105249 | C4: 1169 | D4: 1072 | E4: 6078 | F4: 5341683 | G4: 0 | H4: 1763566 | I4: 0
A5: 2024-11 | B5: 7662664 | C5: 1181 | D5: 1178 | E5: 6488 | F5: 5936779 | G5: 0 | H5: 1725885 | I5: 0
A6: 2024-12 | B6: 11671590 | C6: 1351 | D6: 1486 | E6: 8639 | F6: 9444356 | G6: 0 | H6: 2227234 | I6: 0
A7: 2025-01 | B7: 7840279 | C7: 1119 | D7: 1101 | E7: 7007 | F7: 2061581 | G7: 2399581 | H7: 1883895 | I7: 1495222
A8: 2025-02 | B8: 8650219 | C8: 1162 | D8: 1341 | E8: 7444 | F8: 2096403 | G8: 2632139 | H8: 2116531 | I8: 1805146
A9: 2025-03 | B9: 9908083 | C9: 1229 | D9: 1327 | E9: 8062 | F9: 2239398 | G9: 2891471 | H9: 2544396 | I9: 2232819
A10: 2025-04 | B10: 8768678 | C10: 1152 | D10: 1339 | E10: 7612 | F10: 2132595 | G10: 3171676 | H10: 1902028 | I10: 1562378
A11: 2025-05 | B11: 9258032 | C11: 1151 | D11: 1253 | E11: 8043 | F11: 2054234 | G11: 3219377 | H11: 2317220 | I11: 1667202
A12: 2025-06 | B12: 8543948 | C12: 1134 | D12: 1079 | E12: 7534 | F12: 2159884 | G12: 2985806 | H12: 1945272 | I12: 1452986
A13: 2025-07 | B13: 8845417 | C13: 1118 | D13: 1106 | E13: 7912 | F13: 2082735 | G13: 2985305 | H13: 2031118 | I13: 1746258
A14: 2025-08 | B14: 9434153 | C14: 1179 | D14: 1219 | E14: 8002 | F14: 2444503 | G14: 3241314 | H14: 1968376 | I14: 1779960
A15: 2025-09 | B15: 8229173 | C15: 1136 | D15: 1053 | E15: 7244 | F15: 2084794 | G15: 2554151 | H15: 1899723 | I15: 1690505
... A21: 2026-03 | B21: 6745218 | C21: 666 | D21: 750 | E21: 10128 | F21: 3319368 | G21: 1883254 | H21: 0 | I21: 0
A23: TOTAL | B23: 156097009 | C23: 19257 | D23: 20270

Sheet Productos
A1: PRODUCTOS ROTISERIA - CLASIFICACION ABC
A3: Producto | B3: Ventas ($) | C3: Cantidad | D3: Precio Prom ($) | E3: % Ventas | F3: % Acum
A4: MATAMBRE NINO | B4: 21848114 | C4: 248 | D4: 35085 | E4: 14 | F4: 14
A5: EMPANADA CARNE X 12 UN. | B5: 21267910 | C5: 2520 | D5: 8343 | E5: 13.6 | F5: 27.6
A6: EMPANADA CARNE X 6 UN. | B6: 18840000 | C6: 4367 | D6: 4292 | E6: 12.1 | F6: 39.7
A7: EMPANADA J&Q X 6 UN. | B7: 8315100 | C7: 1937 | D7: 4270 | E7: 5.3 | F7: 45
A8: EMPANADA POLLO X 6 UN. | B8: 7180250 | C8: 1657 | D8: 4321 | E8: 4.6 | F8: 49.6
A9: LENGUA A LA VINAGRETA NINO | B9: 4547066 | C9: 54 | D9: 16005 | E9: 2.9 | F9: 52.5
A10: MIGA TRIP. X 12 UNI. | B10: 4231800 | C10: 494 | D10: 8528 | E10: 2.7 | F10: 55.2
A11: EMPANADA VERDURA X 6 UN. | B11: 4124850 | C11: 965 | D11: 4257 | E11: 2.6 | F11: 57.9
A12: EMPANADA HUMITA X 6 UN. | B12: 3978000 | C12: 936 | D12: 4241 | E12: 2.5 | F12: 60.4
A13: PERNIL DE CERDO HORNEADO NINO | B13: 3952006 | C13: 66 | D13: 22047 | E13: 2.5 | F13: 63
A14: PIZZA C/JAMON NINO | B14: 3599100 | C14: 446 | D14: 7997 | E14: 2.3 | F14: 65.3
A15: EMPANADA CAPRESE X 6 UN. | B15: 3584500 | C15: 834 | D15: 4262 | E15: 2.3 | F15: 67.6
... A67: VITEL TONE NINO | B67: 218 | C67: 0 | D67: 1900 | E67: 0 | F67: 100
A69: Verde = Core (80%) | Amarillo = Complementario (80-95%) | Sin color = Marginal

Sheet Costeo Recetas
A1: COSTEO POR RECETA - INSUMOS ROTISERIA NINO
A2: Precios insumos: mas baratos del POS Feb 2026 × factor costo por rubro (rentabilidad_factor) | Validacion del margen 30%
A4: PRECIOS DE INSUMOS (POS supermercado Feb 2026)
A5: Insumo | B5: Precio Retail | C5: Unidad | D5: Factor Costo | E5: Costo Est. | H5: Fuente
A6: Carne picada especial | B6: 15218 | C6: $/kg | D6: ×0.8 | E6: 12174 | H6: CARNICERIA - MOLIDA ESPECIAL (mas barato Feb 26)
A7: Matambre vacuno crudo | B7: 19806 | C7: $/kg | D7: ×0.8 | E7: 15845 | H7: CARNICERIA - MATAMBRE
A8: Suprema pollo | B8: 12008 | C8: $/kg | D8: ×0.8 | E8: 9606 | H8: POLLO - SUPREMA DE POLLO
A9: Pernil chancho cong. | B9: 5207 | C9: $/kg | D9: ×0.72 | E9: 3749 | H9: CONGELADOS - PERNIL CHANCHO
A10: Lengua vacuna | B10: 11262 | C10: $/kg | D10: ×0.8 | E10: 9010 | H10: CARNICERIA - LENGUA X KG
A11: Paleta cocida | B11: 7650 | C11: $/kg | D11: ×0.55 | E11: 4208 | H11: FIAMBRERIA - PIAMONTESA PALETA 131 (mas barata)
A12: Muzzarella Jumial | B12: 8031 | C12: $/kg | D12: ×0.55 | E12: 4417 | H12: FIAMBRERIA - MUZARELLA JUMIAL
A13: Ricota Jumial | B13: 3840 | C13: $/kg | D13: ×0.55 | E13: 2112 | H13: FIAMBRERIA - RICOTA JUMIAL S/TACC
A14: Tapas empanada x12 | B14: 1150 | C14: $/doc | D14: ×0.7 | E14: 805 | H14: PANIFIC. - VIA VENETO (mas barata)
A15: Pan de miga x25 | B15: 7040 | C15: $/pack | D15: ×0.7 | E15: 4928 | H15: PANIFIC. - LUISANA MIGA X 25 (mas barata)
A16: Harina 0000 | B16: 1037 | C16: $/kg | D16: ×0.72 | E16: 747 | H16: HARINAS - FLORENCIA 0000 1KG
A17: Huevos x6 | B17: 1671 | C17: $/pack | D17: ×0.72 | E17: 1203 | H17: HUEVOS FRESCOS
... A19: Pure tomate 520g | B19: 830 | C19: $/u | D19: ×0.72 | E19: 598 | H19: ALMACEN - ARCOR
A21: COSTEO POR RECETA
A22: Producto / Insumo | B22: Cantidad | C22: Unidad | D22: Precio Retail | E22: Costo (×0.70) | F22: PVP | G22: Margen % | H22: % Ventas rotis.
A23: EMPANADA CARNE x12 | F23: 10702 | H23: 49.8%
A24: Carne picada especial | B24: 0.35 | C24: kg | D24: 5326 | E24: 4261
A25: Tapas empanada x12 | B25: 1 | C25: doc | D25: 1150 | E25: 805
A26: Cebolla | B26: 0.15 | C26: kg | D26: 225 | E26: 162
A27: Huevo (1/2) | B27: 0.5 | C27: u | D27: 140 | E27: 100
A28: Condimentos/grasa | B28: 1 | C28: lote | D28: 300 | E28: 216
A29: COSTO TOTAL | E29: 5544 | F29: 10702 | G29: 48%
A30: EMPANADA J&Q x6 | F30: 5329 | H30: 5.2%
A31: Paleta cocida | B31: 0.12 | C31: kg | D31: 918 | E31: 505
A32: Muzzarella Jumial | B32: 0.1 | C32: kg | D32: 803 | E32: 442
A33: Tapas empanada x6 | B33: 0.5 | C33: doc | D33: 575 | E33: 402
A34: Condimentos | B34: 1 | C34: lote | D34: 150 | E34: 108
A35: COSTO TOTAL | E35: 1457 | F35: 5329 | G35: 73%
A36: MATAMBRE NINO (por kg) | F36: 44951 | H36: 13.9%
A37: Matambre vacuno crudo | B37: 1.4 | C37: kg | D37: 27728 | E37: 22183
A38: Condimentos/vinagre | B38: 1 | C38: lote | D38: 500 | E38: 360
A39: COSTO TOTAL | E39: 22543 | F39: 44951 | G39: 50%
A40: PIZZA MUZZARELLA | F40: 7287 | H40: 2.2%
A41: Harina 0000 | B41: 0.25 | C41: kg | D41: 259 | E41: 187
A42: Muzzarella Jumial | B42: 0.2 | C42: kg | D42: 1606 | E42: 883
A43: Salsa tomate | B43: 0.15 | C43: kg | D43: 239 | E43: 172
...

Sheet Sensibilizacion
A1: ANALISIS DE SENSIBILIDAD - MARGEN DE CONTRIBUCION
A3: Escenarios variando Margen Bruto y Merma:
A5: Escenario | B5: Margen Bruto % | C5: Merma % | D5: Margen Contrib ($) | E5: MC % s/Ventas | F5: Estado
A6: Pesimista | B6: 25% | C6: 8% | D6: -4517736 | E6: -40.9% | F6: DEFICIT
A7: Conservador | B7: 28% | C7: 6% | D7: -3965218 | E7: -35.9% | F7: DEFICIT
A8: Base | B8: 30% | C8: 5% | D8: -3633707 | E8: -32.9% | F8: DEFICIT
A9: Optimista | B9: 33% | C9: 3% | D9: -3081190 | E9: -27.9% | F9: DEFICIT
A10: Ideal | B10: 35% | C10: 2% | D10: -2749680 | E10: -24.9% | F10: DEFICIT
A13: Punto de equilibrio por escenario:
A14: Escenario | B14: Margen % | C14: Merma % | D14: Vtas Equilibrio ($) | E14: Cobertura % | F14: Estado
A15: Pesimista | B15: 25% | C15: 8% | D15: 46556033 | E15: 24% | F15: INSUFICIENTE
A16: Conservador | B16: 28% | C16: 6% | D16: 33422401 | E16: 33% | F16: INSUFICIENTE
A17: Base | B17: 30% | C17: 5% | D17: 28584173 | E17: 39% | F17: INSUFICIENTE
A18: Optimista | B18: 33% | C18: 3% | D18: 23028234 | E18: 48% | F18: INSUFICIENTE
A19: Ideal | B19: 35% | C19: 2% | D19: 20623114 | E19: 54% | F19: INSUFICIENTE
A22: NOTA: Si la empresa obtiene certificado MiPyME, las contribuciones bajan de 20.74% a 18% SUSS, mejorando todos los escenarios.

Sheet Comisiones Financieras
A1: COMISIONES Y CARGA FINANCIERA - ROTISERIA NINO
A2: Mix de medios de pago: meses completos Dic 2025 - Feb 2026. Fuente: POS NINO. Celdas en amarillo = parametros ajustables.
A4: 1. MIX DE MEDIOS DE PAGO (real POS - meses completos)
A5: Medio de Pago | B5: Mix % (real) | C5: Monto mensual ($) | F5: Nota
A6: Efectivo | B6: 0.47065784 | C6: =ROUND('Estructura Costos'!B6*B6,0) -> 5200932 | F6: No genera comisiones ni ICH
A7: Tarjeta Debito | B7: 0.32712725 | C7: =ROUND('Estructura Costos'!B6*B7,0) -> 3614869 | F7: Comision 1.2% | Acreditacion 3 dias habiles
A8: Tarjeta Credito | B8: 0.096427236 | C8: =ROUND('Estructura Costos'!B6*B8,0) -> 1065554 | F8: Comision 3.0% | Acreditacion 18 dias habiles
A9: Billetera Virtual | B9: 0.10578767 | C9: =ROUND('Estructura Costos'!B6*B9,0) -> 1168990 | F9: Comision 1.5% | Acreditacion 2 dias habiles
A10: TOTAL | B10: =SUM(B6:B9) -> 1 | C10: =SUM(C6:C9) -> 11050345 | F10: Debe sumar 100%
A12: 2. PARAMETROS COMERCIALES (celdas en amarillo - ajustar segun contrato)
A13: Modificar estas celdas para simular diferentes contratos con procesadoras. NO modificar el mix % (viene del POS).
A14: Canal | B14: Tasa comision | C14: Dias acreditacion | F14: Fuente / Nota
A15: Efectivo | B15: 0 | C15: 0 | F15: No aplica
A16: Tarjeta Debito | B16: 0.012 | C16: 3 | F16: Tasa promedio procesadoras. AJUSTAR con contrato real
A17: Tarjeta Credito | B17: 0.03 | C17: 18 | F17: Tasa promedio procesadoras. AJUSTAR con contrato real
A18: Billetera Virtual | B18: 0.015 | C18: 2 | F18: Mercado Pago y otras. AJUSTAR
A20: TNA costo financiero (demora acreditacion) | B20: 0.4 | F20: Tasa Nominal Anual. Cred. comercial Mar 2026. AJUSTAR
A22: 3. CALCULO DE COMISIONES POR CANAL
A23: Formula: Comision = Ventas ('Estructura Costos'!B6) x Mix% (col B arriba) x Tasa comision (Bloque 2)
A24: Canal | B24: Monto ventas ($) | C24: Tasa | D24: Comision ($) | F24: Formula explicada
A25: Efectivo | B25: =C6 -> 5200932 | C25: =B15 -> 0 | D25: =ROUND(B25*C25,0) -> 0 | F25: No aplica (el efectivo no tiene comision de procesadora)
A26: Tarjeta Debito | B26: =C7 -> 3614869 | C26: =B16 -> 0.012 | D26: =ROUND(B26*C26,0) -> 43378
A27: Tarjeta Credito | B27: =C8 -> 1065554 | C27: =B17 -> 0.03 | D27: =ROUND(B27*C27,0) -> 31967
A28: Billetera Virtual | B28: =C9 -> 1168990 | C28: =B18 -> 0.015 | D28: =ROUND(B28*C28,0) -> 17535
A29: SUBTOTAL COMISIONES | D29: =SUM(D25:D28) -> 92880
A31: 4. COSTO FINANCIERO POR DEMORA EN ACREDITACION
A32: Formula: Costo = Monto canal x TNA x Dias acreditacion / 365 (costo de oportunidad del capital inmovilizado)
A33: Canal | B33: Monto ($) | C33: TNA | D33: Dias acred. | E33: Costo ($) | F33: Formula explicada
A34: Tarjeta Debito | B34: =C7 -> 3614869 | C34: =B20 -> 0.4 | D34: =C16 -> 3 | E34: =ROUND(B34*C34*D34/365,0) -> 11885
A35: Tarjeta Credito | B35: =C8 -> 1065554 | C35: =B20 -> 0.4 | D35: =C17 -> 18 | E35: =ROUND(B35*C35*D35/365,0) -> 21019
A36: Billetera Virtual | B36: =C9 -> 1168990 | C36: =B20 -> 0.4 | D36: =C18 -> 2 | E36: =ROUND(B36*C36*D36/365,0) -> 2562
A37: SUBTOTAL COSTO FINANCIERO | E37: =SUM(E34:E36) -> 35466
A39: 5. IMPUESTO AL CREDITO Y DEBITO BANCARIO - ICH (Ley 25.413)
A40: Concepto | B40: Monto ($) | C40: % s/Ventas | F40: Fuente normativa
A41: Ventas totales | B41: ='Estructura Costos'!B6 -> 11050346 | C41: 100.0% | F41: Base de calculo
A42: (-) Efectivo (no pasa por banco, 47.1%) | B42: =-'Estructura Costos'!B6*B6 -> -5200932 | C42: =B6 -> 0.47065784 | F42: El efectivo no genera debitos/creditos bancarios
A43: Base imponible ICH (monto bancarizado) | B43: =B41+B42 -> 5849414 | C43: =1-B6 -> 0.52934216 | F43: V x (1 - %efectivo). Ley 25.413 Art. 1
A44: Alicuota ICH (0.6% debitos + 0.6% creditos) | B44: 0.012 | F44: Ley 25.413 Art. 1. Aplica sobre debitos Y creditos bancarios
A45: ICH TOTAL | B45: =ROUND(B43*B44,0) -> 70193 | C45: =B45/B41 -> 0.0063521088 | F45: Solo sobre monto bancarizado. Ley 25.413
A47: 6. RESUMEN TOTAL CARGA FINANCIERA MENSUAL
...

Sheet Memoria de Calculo
A1: MEMORIA DE CALCULO - DEMOSTRACION DE FORMULAS Y FUENTES NORMATIVAS
A2: Cada linea muestra: concepto, formula con valores, resultado, y fuente normativa/regulatoria
A4: 1. VENTAS MENSUALES DESESTACIONALIZADAS
A5: Concepto | B5: Formula / Desarrollo | C5: Resultado ($) | D5: Fuente normativa
A6: Ventas brutas ventana | B6: Suma importe POS ROTISERIA 16/02/2026-18/03/2026 (31 dias) | C6: 11369307 | D6: 4 Excel POS (ReporteMovimientosItemEnComprobantes 1/2/22/3)
A7: Venta diaria promedio | B7: $11,369,307 / 31 dias = $366,752/dia | C7: 366752 | D7: Calculo propio
A8: Indice estacional Ene 2025 | B8: Vta diaria Ene/Promedio diario anual = 0.8102 | D8: Parquet historico Oct 2024-Dic 2025 (meses completos)
A9: Indice estacional Feb 2025 | B9: Vta diaria Feb/Promedio diario anual = 0.9896 | D9: Parquet historico Oct 2024-Dic 2025 (meses completos)
A10: Indice estacional Mar 2025 | B10: Vta diaria Mar/Promedio diario anual = 1.0239 | D10: Parquet historico Oct 2024-Dic 2025 (meses completos)
A11: Indice estacional Abr 2025 | B11: Vta diaria Abr/Promedio diario anual = 0.9363 | D11: Parquet historico Oct 2024-Dic 2025 (meses completos)
A12: Indice estacional May 2025 | B12: Vta diaria May/Promedio diario anual = 0.9567 | D12: Parquet historico Oct 2024-Dic 2025 (meses completos)
A13: Indice estacional Jun 2025 | B13: Vta diaria Jun/Promedio diario anual = 0.9123 | D13: Parquet historico Oct 2024-Dic 2025 (meses completos)
A14: Indice estacional Jul 2025 | B14: Vta diaria Jul/Promedio diario anual = 0.9140 | D14: Parquet historico Oct 2024-Dic 2025 (meses completos)
A15: Indice estacional Ago 2025 | B15: Vta diaria Ago/Promedio diario anual = 0.9749 | D15: Parquet historico Oct 2024-Dic 2025 (meses completos)
A16: Indice estacional Sep 2025 | B16: Vta diaria Sep/Promedio diario anual = 0.8787 | D16: Parquet historico Oct 2024-Dic 2025 (meses completos)
A17: Indice estacional Dic 2025 | B17: Vta diaria Dic/Promedio diario anual = 1.6034 | D17: Parquet historico Oct 2024-Dic 2025 (meses completos)
A18: Indice ponderado ventana | B18: Promedio ponderado por dias reales en ventana = 1.0095 | D18: Ponderacion: dias Feb × idx Feb + dias Mar × idx Mar
A19: VENTAS MENSUALES | B19: ($11,369,307 / 31) × 30.4167 / 1.0095 | C19: 11050346 | D19: 30.4167 = dias promedio por mes (365.25/12)
A20: V = $11,050,346 incluye IVA (97% Factura B). Los precios POS son de gondola, incluyen IVA. Art. 7 Ley 24.240 Defensa del Consumidor.
A22: 2. COSTO DE MERCADERIA VENDIDA
A23: Concepto | B23: Formula / Desarrollo | C23: Resultado ($) | D23: Fuente normativa
A24: Margen bruto del sistema | B24: rentabilidad_factor del POS = 0.30 para ROTISERIA → CMV = V × (1 - 0.30) | D24: Parametro POS supermercado NINO
A25: CMV | B25: $11,050,346 × 0.70 = $7,735,242 | C25: -7735242 | D25: rentabilidad_factor = 0.30 para todos los productos ROTISERIA
A26: MARGEN BRUTO | B26: $11,050,346 - $7,735,242 = $3,315,104 | C26: 3315104 | D26: V × MG (V × 0.30)
A28: 3. COSTOS LABORALES - DEMOSTRACION COMPLETA
A29: Concepto | B29: Formula / Desarrollo | C29: Resultado ($) | D29: Fuente normativa
A30: Basico remunerativo (c/u) | B30: Escala salarial CCT 130/75, Categoria Auxiliar Especializado A | C30: 1080274 | D30: CCT 130/75 Empleados de Comercio. Escala FAECYS Dic 2025 - Mar 2026
A31: No Remunerativo (c/u) | B31: Suma fija pactada en acuerdo paritario | C31: 100000 | D31: Acuerdo paritario FAECYS-CAC Dic 2025
A32: Sueldo bruto por empleado | B32: $1,080,274 + $100,000 = $1,180,274 | C32: 1180274 | D32: Rem + NR. El NR no genera contribuciones patronales
A33: SUELDOS BRUTOS (3 empl.) | B33: $1,180,274 × 3 = $3,540,822 | C33: -3540822 | D33: Base F.930 (solo rem): $1,080,274 × 3 = $3,240,822
A35: CONTRIBUCIONES PATRONALES - Desglose F.930 (solo sobre remunerativo)
A36: Jubilacion (SIPA) | B36: $3,240,822 × 12.71% = $411,908 | C36: -411908 | D36: Ley 24.241 Art. 11. Alicuota Dto. 814/2001 Sector Servicios
A37: PAMI (INSSJP) | B37: $3,240,822 × 1.58% = $51,205 | C37: -51205 | D37: Ley 19.032 Art. 8. Alicuota Dto. 814/2001
A38: Asignaciones Familiares | B38: $3,240,822 × 5.56% = $180,190 | C38: -180190 | D38: Ley 24.714 Art. 5. Alicuota Dto. 814/2001 Sector Servicios
A39: Fondo Nacional de Empleo | B39: $3,240,822 × 0.89% = $28,843 | C39: -28843 | D39: Ley 24.013 Art. 145. Alicuota unica
A40: Obra Social patronal | B40: $3,240,822 × 6.00% = $194,449 | C40: -194449 | D40: Ley 23.660 Art. 16 inc. a). 6% empleador
A41: ART (estimado) | B41: $3,240,822 × 3.00% = $97,225 | C41: -97225 | D41: Ley 24.557. Alicuota variable segun ART y siniestralidad. 3% estimado
A42: TOTAL CONTRIBUCIONES | B42: $3,240,822 × 29.74% = $963,820 | C42: -963820 | D42: Suma alicuotas: 12.71+1.58+5.56+0.89+6.00+3.00 = 29.74%
A43: Empresa NO MiPyME. Si obtiene certificado MiPyME (Ley 27.264), SIPA baja de 12.71% a ~10.17% (Dto. 128/2019)
A45: PRESENTISMO - basico bruto | B45: 8.33% × $1,080,274 = $89,987 × 3 empleados | C45: -270069 | D45: Art. 40 CCT 130/75: 8.33% del sueldo basico. Es REMUNERATIVO, genera CP
...
